# 13장: 오류 처리 - Handling Errors

이전 장에서는 서버 액션을 사용하여 데이터를 변경하는 방법을 배웠습니다. 이번 장에서는 JavaScript의 `try/catch` 문과 Next.js API를 사용하여 오류를 _우아하게_ 처리하는 방법을 알아보겠습니다.

이번 장에서 다룰 주제입니다.

- 라우트 세그먼트에서 오류를 잡아내고 사용자에게 대체 UI를 보여주기 위해 특별한 `error.tsx` 파일을 사용하는 방법.
- 404 오류(존재하지 않는 리소스)를 처리하기 위해 `notFound` 함수와 `not-found` 파일을 사용하는 방법.

---

## 서버 액션에 `try/catch` 추가하기 - Adding try/catch to Server Actions

먼저, 서버 액션에 JavaScript의 `try/catch` 문을 추가하여 오류를 우아하게 처리할 수 있도록 해봅시다.

이미 방법을 알고 있다면 서버 액션을 몇 분 동안 업데이트하거나 아래 코드를 복사하세요:

`/app/lib/actions.ts`

```ts
export async function createInvoice(formData: FormData) {
  const { customerId, amount, status } = CreateInvoice.parse({
    customerId: formData.get("customerId"),
    amount: formData.get("amount"),
    status: formData.get("status"),
  });

  const amountInCents = amount * 100;
  const date = new Date().toISOString().split("T")[0];

  try {
    await sql`
      INSERT INTO invoices (customer_id, amount, status, date)
      VALUES (${customerId}, ${amountInCents}, ${status}, ${date})
    `;
  } catch (error) {
    return {
      message: "Database Error: Failed to Create Invoice.",
    };
  }

  revalidatePath("/dashboard/invoices");
  redirect("/dashboard/invoices");
}
```

`/app/lib/actions.ts`

```ts
export async function updateInvoice(id: string, formData: FormData) {
  const { customerId, amount, status } = UpdateInvoice.parse({
    customerId: formData.get("customerId"),
    amount: formData.get("amount"),
    status: formData.get("status"),
  });

  const amountInCents = amount * 100;

  try {
    await sql`
        UPDATE invoices
        SET customer_id = ${customerId}, amount = ${amountInCents}, status = ${status}
        WHERE id = ${id}
      `;
  } catch (error) {
    return { message: "Database Error: Failed to Update Invoice." };
  }

  revalidatePath("/dashboard/invoices");
  redirect("/dashboard/invoices");
}
```

`/app/lib/actions.ts`

```ts
export async function deleteInvoice(id: string) {
  try {
    await sql`DELETE FROM invoices WHERE id = ${id}`;
    revalidatePath("/dashboard/invoices");
    return { message: "Deleted Invoice." };
  } catch (error) {
    return { message: "Database Error: Failed to Delete Invoice." };
  }
}
```

`try/catch` 블록 밖에서 `redirect`가 호출되는 것을 주목하세요. 이는 `redirect`가 오류를 던지기 때문에 `catch` 블록에 의해 잡힐 것입니다. 이를 피하기 위해 `try/catch` **후에** `redirect`를 호출할 수 있습니다. `try`가 성공적이라면 `redirect`에 도달할 수 있습니다.

이제 서버 액션에서 오류가 발생했을 때 무슨 일이 일어나는지 확인해봅시다. 예를 들어, `deleteInvoice` 액션에서 함수의 상단에서 오류를 던져보세요:

`/app/lib/actions.ts`

```ts
export async function deleteInvoice(id: string) {
  throw new Error("Failed to Delete Invoice");

  // 도달할 수 없는 코드 블록
  try {
    await sql`DELETE FROM invoices WHERE id = ${id}`;
    revalidatePath("/dashboard/invoices");
    return { message: "Deleted Invoice" };
  } catch (error) {
    return { message: "Database Error: Failed to Delete Invoice" };
  }
}
```

송장을 삭제하려고 하면 localhost에서 오류를 볼 수 있습니다.

이러한 오류를 보는 것은 개발하는 동안 잠재적인 문제를 조기에 발견할 수 있어 도움이 됩니다. 그러나 사용자에게 오류를 보여주어 갑작스러운 실패를 방지하고 애플리케이션이 계속 실행될 수 있도록 하고 싶습니다.

이때 Next.js의 `error.tsx` 파일이 사용됩니다.

> <https://nextjs.org/docs/app/api-reference/file-conventions/error>

## `error.tsx`로 모든 오류 처리하기 - Handling all errors with error.tsx

`error.tsx` 파일은 라우트 세그먼트의 UI 경계를 정의하는 데 사용할 수 있습니다. 예기치 않은 오류를 **모두** 잡아내고 사용자에게 대체 UI를 표시할 수 있게 해줍니다.

`/dashboard/invoices` 폴더 안에 `error.tsx`라는 새 파일을 만들고 다음 코드를 붙여넣으세요:

`/dashboard/invoices/error.tsx`

```tsx
"use client";

import { useEffect } from "react";

export default function Error({ error, reset }: { error: Error & { digest?: string }; reset: () => void }) {
  useEffect(() => {
    // 선택적으로 오류를 오류 보고 서비스에 로깅
    console.error(error);
  }, [error]);

  return (
    <main className="flex h-full flex-col items-center justify-center">
      <h2 className="text-center">무언가 잘못되었습니다!</h2>
      <button
        className="mt-4 rounded-md bg-blue-500 px-4 py-2 text-sm text-white transition-colors hover:bg-blue-400"
        onClick={
          // 송장 라우트를 다시 렌더링하려고 시도하여 복구를 시도
          () => reset()
        }>
        다시 시도
      </button>
    </main>
  );
}
```

위 코드에 대해 몇 가지 주목할 점이 있습니다:

- **"use client"** - `error.tsx`는 클라이언트 컴포넌트여야 합니다.
- 두 개의 props를 받습니다:
  - `error`: 이 객체는 JavaScript의 네이티브 `Error` 객체의 인스턴스입니다.
    <https://developer.mozilla.org/en-US/docs/Web/JavaScript/Reference/Global_Objects/Error>
  - `reset`: 이 함수는 오류 경계를 리셋합니다. 실행될 때, 함수는 라우트 세그먼트를 다시 렌더링하려고 시도합니다.

송장을 다시 삭제하려고 하면 다음 UI를 볼 수 있습니다:

![/assets/Learn_Nextjs/image_url__2Flearn_2Flight_2Ferr_554b09369fba4056a.png](/assets/Learn_Nextjs/image_url__2Flearn_2Flight_2Ferr_554b09369fba4056a.png)

---

## `notFound` 함수를 사용하여 404 오류 처리하기 - Handling 404 errors with the notFound function

오류를 우아하게 처리하는 또 다른 방법은 `notFound` 함수를 사용하는 것입니다. `error.tsx`가 **모든** 오류를 잡는 데 유용한 반면, `notFound`는 존재하지 않는 리소스를 가져오려고 할 때 사용할 수 있습니다.

예를 들어, <http://localhost:3000/dashboard/invoices/2e94d1ed-d220-449f-9f11-f0bbceed9645/edit> 을 방문해보세요.

이것은 데이터베이스에 존재하지 않는 가짜 UUID입니다.

`error.tsx`가 `/invoices`의 자식 라우트인 곳에 정의되어 있기 때문에 즉시 작동하는 것을 볼 수 있습니다.

그러나 더 구체적으로 처리하고 싶다면, 사용자가 접근하려는 리소스를 찾을 수 없다고 알려주는 404 오류를 표시할 수 있습니다.

리소스를 찾을 수 없음을 확인하기 위해 `data.ts`의 `fetchInvoiceById` 함수로 가서 반환된 `invoice`를 콘솔 로깅해보세요:

`/app/lib/data.ts`

```ts
export async function fetchInvoiceById(id: string) {
  noStore();
  try {
    // ...

    console.log(invoice); // Invoice는 빈 배열 []
    return invoice[0];
  } catch (error) {
    console.error("Database Error:", error);
    throw new Error("Failed to fetch invoice.");
  }
}
```

이제 데이터베이스에 송장이 존재하지 않는다는 것을 알았으니, `notFound`를 사용하여 처리해봅시다. `/dashboard/invoices/[id]/edit/page.tsx`로 이동하여 `'next/navigation'`에서 `{ notFound }`를 가져오세요.

그런 다음, 송장이 존재하지 않을 경우 `notFound`를 호출하는 조건문을 사용할 수 있습니다:

`/dashboard/invoices/[id]/edit/page.tsx`

```tsx
import { fetchInvoiceById, fetchCustomers } from "@/app/lib/data";
import { updateInvoice } from "@/app/lib/actions";
import { notFound } from "next/navigation";

export default async function Page({ params }: { params: { id: string } }) {
  const id = params.id;
  const [invoice, customers] = await Promise.all([fetchInvoiceById(id), fetchCustomers()]);

  if (!invoice) {
    notFound();
  }

  // ...
}
```

완벽합니다! `<Page>`는 특정 송장을 찾을 수 없는 경우 오류를 발생시킬 것입니다. 사용자에게 오류 UI를 표시하려면 `/edit` 폴더 안에 `not-found.tsx` 파일을 생성하세요.

![/assets/Learn_Nextjs/image_url__2Flearn_2Flight_2Fnot_d83ecd445db345bda.png](/assets/Learn_Nextjs/image_url__2Flearn_2Flight_2Fnot_d83ecd445db345bda.png)

그런 다음, `not-found.tsx` 파일 안에 다음 코드를 붙여넣으세요:

`/dashboard/invoices/[id]/edit/not-found.tsx`

```tsx
import Link from "next/link";
import { FaceFrownIcon } from "@heroicons/react/24/outline";

export default function NotFound() {
  return (
    <main className="flex h-full flex-col items-center justify-center gap-2">
      <FaceFrownIcon className="w-10 text-gray-400" />
      <h2 className="text-xl font-semibold">404 Not Found</h2>
      <p>요청한 송장을 찾을 수 없습니다.</p>
      <Link
        href="/dashboard/invoices"
        className="mt-4 rounded-md bg-blue-500 px-4 py-2 text-sm text-white transition-colors hover:bg-blue-400">
        돌아가기
      </Link>
    </main>
  );
}
```

라우트를 새로고침하면 이제 다음 UI를 볼 수 있습니다:

![/assets/Learn_Nextjs/image_url__2Flearn_2Flight_2F404_1e8e9b5e1b7849afa.png](/assets/Learn_Nextjs/image_url__2Flearn_2Flight_2F404_1e8e9b5e1b7849afa.png)

`notFound`는 `error.tsx`보다 우선순위가 높으므로, 더 구체적인 오류를 처리하고 싶을 때 이를 활용할 수 있습니다!

---

## 추가 학습 - Further reading

Next.js에서 오류 처리에 대해 더 알아보려면 다음 문서를 확인하세요:

- 오류 처리  
  <https://nextjs.org/docs/app/building-your-application/routing/error-handling>
- `error.js` API 참조  
  <https://nextjs.org/docs/app/api-reference/file-conventions/error>
- `notFound()` API 참조  
  <https://nextjs.org/docs/app/api-reference/functions/not-found>
- `not-found.js` API 참조  
  <https://nextjs.org/docs/app/api-reference/file-conventions/not-found>
